#VRML_SIM R2023b utf8

EXTERNPROTO "https://raw.githubusercontent.com/cyberbotics/webots/R2023b/projects/objects/backgrounds/protos/TexturedBackground.proto"
EXTERNPROTO "https://raw.githubusercontent.com/cyberbotics/webots/R2023b/projects/objects/backgrounds/protos/TexturedBackgroundLight.proto"
EXTERNPROTO "https://raw.githubusercontent.com/cyberbotics/webots/R2023b/projects/objects/floors/protos/RectangleArena.proto"
EXTERNPROTO "https://raw.githubusercontent.com/cyberbotics/webots/R2023b/projects/objects/solids/protos/SolidBox.proto"

WorldInfo {
}
Viewpoint {
  orientation 0.3866180355122797 -0.06676606051852986 -0.9198199757449617 3.4566452096657128
  position 1.9244990204777577 -0.416435172609461 1.59850100704477
}
TexturedBackground {
}
TexturedBackgroundLight {
}
RectangleArena {
}
SolidBox {
  translation 0.13 0.07 0.04
  name "box(2)"
  size 0.1 0.1 0.1
}
SolidBox {
  translation -0.18 -0.45 0.04
  name "box(1)"
  size 0.1 0.1 0.1
}
Robot {
  translation 0.39479499624184233 -0.015255855261334822 0.039891387427565816
  rotation 0.00010528179380294808 0.03840704254883856 0.9992621718039744 0.025544757841023318
  children [
    DistanceSensor {
      translation -0.05 -0.04 0
      rotation 0 0 1 -2.3561996938995744
      children [
        DEF sensor1 Shape {
          appearance PBRAppearance {
            baseColor 0.1 0.3 1
            roughness 1
            metalness 0
          }
          geometry Box {
            size 0.01 0.01 0.01
          }
        }
      ]
      name "Rsensor"
      boundingObject USE sensor1
      physics Physics {
      }
    }
    DistanceSensor {
      translation 0.05 -0.04 0
      rotation 0 0 1 -1.0471996938995747
      children [
        DEF sensor1 Shape {
          appearance PBRAppearance {
            baseColor 0.1 0.3 1
            roughness 1
            metalness 0
          }
          geometry Box {
            size 0.01 0.01 0.01
          }
        }
      ]
      name "Lsensor"
      boundingObject USE sensor1
      physics Physics {
      }
    }
    HingeJoint {
      jointParameters HingeJointParameters {
        position 7164.353904862039
        anchor -0.07 0.03 -0.0201
      }
      device [
        RotationalMotor {
          name "Lmotor2"
        }
      ]
      endPoint Solid {
        translation -0.06998905576644257 0.030225098070256733 -0.020217305036334753
        rotation 0.6145511744178994 0.4950917705734297 0.6141750505613582 2.2212973941744187
        children [
          DEF wheel Shape {
            appearance PBRAppearance {
              baseColor 0.2 0 1
              roughness 1
              metalness 0
            }
            geometry Cylinder {
              height 0.01
              radius 0.02
            }
          }
        ]
        name "solid(4)"
        boundingObject USE wheel
        physics Physics {
        }
        linearVelocity 0.001896837601931031 -0.08788115219983103 0.00035590931117057884
        angularVelocity 4.394738847844466 0.10746549737159923 -0.00045833505196804915
      }
    }
    HingeJoint {
      jointParameters HingeJointParameters {
        position 7164.3535484591275
        anchor -0.07 -0.03 -0.0201
      }
      device [
        RotationalMotor {
          name "Lmotor1"
        }
      ]
      endPoint Solid {
        translation -0.06999074540161077 -0.029772748947426608 -0.020217249438709905
        rotation 0.5681062968362802 0.5958512657717272 0.567641175896533 2.066115480680729
        children [
          DEF wheel Shape {
            appearance PBRAppearance {
              baseColor 0.2 0 1
              roughness 1
              metalness 0
            }
            geometry Cylinder {
              height 0.01
              radius 0.02
            }
          }
        ]
        name "solid(3)"
        boundingObject USE wheel
        physics Physics {
        }
        linearVelocity 0.0021523972809014626 -0.08787092341625803 0.0003623675714316902
        angularVelocity 4.39473865897231 0.10746547256176218 -0.00045882034708012037
      }
    }
    HingeJoint {
      jointParameters HingeJointParameters {
        position 11265.854629955611
        anchor 0.07 0.03 -0.02
      }
      device [
        RotationalMotor {
          name "Rmotor2"
        }
      ]
      endPoint Solid {
        translation 0.07000971092368707 0.02999582675878001 -0.02001109355252385
        rotation -0.051633908573497 -0.9973321724015672 -0.05159919939489884 4.710546726337694
        children [
          DEF wheel Shape {
            appearance PBRAppearance {
              baseColor 0.2 0 1
              roughness 1
              metalness 0
            }
            geometry Cylinder {
              height 0.01
              radius 0.02
            }
          }
        ]
        name "solid(2)"
        boundingObject USE wheel
        physics Physics {
        }
        linearVelocity 0.0019040239531055922 -0.08789451119586388 -6.3504827558657674e-06
        angularVelocity 4.394739031056556 0.10746544304514236 -0.0004584260904615373
      }
    }
    HingeJoint {
      jointParameters HingeJointParameters {
        position 11265.85446024627
        anchor 0.07 -0.03 -0.02
      }
      device [
        RotationalMotor {
          name "Rmotor1"
        }
      ]
      endPoint Solid {
        translation 0.07001075223367324 -0.03000422460132122 -0.020011122679504896
        rotation -0.05154942945311759 -0.9973409054527279 -0.051514800143171814 4.710555451106578
        children [
          DEF wheel Shape {
            appearance PBRAppearance {
              baseColor 0.2 0 1
              roughness 1
              metalness 0
            }
            geometry Cylinder {
              height 0.01
              radius 0.02
            }
          }
        ]
        name "solid(1)"
        boundingObject USE wheel
        physics Physics {
        }
        linearVelocity 0.0021529250639368354 -0.08789159451045096 -9.68806256548321e-06
        angularVelocity 4.394738928787565 0.10746546834877807 -0.0004588181995270077
      }
    }
    DEF body Solid {
      translation 0 0 -0.01
      children [
        DEF body Shape {
          appearance PBRAppearance {
            baseColor 1 0.6 1
            roughness 1
            metalness 0
          }
          geometry Box {
            size 0.14 0.08 0.06
          }
        }
      ]
      boundingObject USE body
      physics Physics {
      }
    }
  ]
  boundingObject USE body
  physics Physics {
  }
  controller "my_controller2"
  linearVelocity 0.0019644491502063587 -0.08821987659154883 -0.0002960742932333496
  angularVelocity 0.00016603704010641082 -0.004447627533458503 0.00398926041667019
}
